<?xml version="1.0" encoding="utf-8"?>
<!-- This URDF was automatically created by SolidWorks to URDF Exporter! Originally created by Stephen Brawner (brawner@gmail.com) 
     Commit Version: 1.6.0-4-g7f85cfe  Build Version: 1.6.7995.38578
     For more information, please see http://wiki.ros.org/sw_urdf_exporter -->
<robot name="newmanip_description">

  <link name="base_link"/>
  <joint name="base_to_base_plate" type="fixed">
    <parent link="base_link"/>
    <child link="rigid_base_plate"/>
    <origin xyz="0 0 0" rpy="0 0 0"/>
  </joint>

  <link name="rigid_base_plate">
    <inertial>
      <origin xyz="-0.00224854905210758 -2.22044604925031E-16 -1.11022302462516E-16" rpy="0 0 0" />
      <mass value="0.139707136084498" />
      <inertia ixx="0.000362153855961995" ixy="-1.86445498629699E-19" ixz="6.69074444268395E-18" iyy="0.000407966760717313" iyz="-2.52141086441536E-18" izz="0.000769538503612289" />
    </inertial>
    <visual>
      <origin xyz="0 0 0" rpy="0 0 0" />
      <geometry>
        <mesh filename="package://newmanip_description/meshes/rigid_base_plate.STL" />
      </geometry>
      <material name="">
        <color rgba="0.96078431372549 0.96078431372549 0.964705882352941 1" />
      </material>
    </visual>
    <collision>
      <origin xyz="0 0 0" rpy="0 0 0" />
      <geometry>
        <mesh filename="package://newmanip_description/meshes/rigid_base_plate.STL" />
      </geometry>
    </collision>
  </link>
  <link name="manipulator_base_plate">
    <inertial>
      <origin xyz="1.22886286373358E-05 1.11022302462516E-16 1.11022302462516E-16" rpy="0 0 0" />
      <mass value="0.0862820052494155" />
      <inertia ixx="0.000123802300064541" ixy="-2.58850064594347E-19" ixz="1.72303453251338E-18" iyy="0.000121470538062705" iyz="-8.61839529210846E-19" izz="0.00024491332977204" />
    </inertial>
    <visual>
      <origin xyz="0 0 0" rpy="0 0 0" />
      <geometry>
        <mesh filename="package://newmanip_description/meshes/manipulator_base_plate.STL" />
      </geometry>
      <material name="">
        <color rgba="0.0980392156862745 0.0980392156862745 0.0980392156862745 1" />
      </material>
    </visual>
    <collision>
      <origin xyz="0 0 0" rpy="0 0 0" />
      <geometry>
        <mesh filename="package://newmanip_description/meshes/manipulator_base_plate.STL" />
      </geometry>
    </collision>
  </link>
  <joint name="manipulaotr_base_plate_j_base_plate" type="revolute">
    <origin xyz="0 0 0.035" rpy="0 0 0" />
    <parent link="rigid_base_plate" />
    <child link="manipulator_base_plate" />
    <axis xyz="0 0 1" />
    <limit lower="0" upper="6.28" effort="5" velocity="300" />
  </joint>
  <link name="link1_base_connector">
    <inertial>
      <origin xyz="-0.00250683727782453 7.21501936895574E-06 0.0284780963824992" rpy="0 0 0" />
      <mass value="0.3101493034797" />
      <inertia ixx="0.000225770602403096" ixy="-1.53108847872636E-11" ixz="-4.44856677198981E-08" iyy="0.000328764440352947" iyz="-9.00769232145696E-09" izz="0.000429446427553537" />
    </inertial>
    <visual>
      <origin xyz="0 0 0" rpy="0 0 0" />
      <geometry>
        <mesh filename="package://newmanip_description/meshes/link1_base_connector.STL" />
      </geometry>
      <material name="">
        <color rgba="0.768627450980392 0.207843137254902 0.152941176470588 1" />
      </material>
    </visual>
    <collision>
      <origin xyz="0 0 0" rpy="0 0 0" />
      <geometry>
        <mesh filename="package://newmanip_description/meshes/link1_base_connector.STL" />
      </geometry>
    </collision>
  </link>
  <joint name="link1_base_connector_j_base_plate" type="fixed">
    <origin xyz="0 0 0" rpy="0 0 0" />
    <parent link="manipulator_base_plate" />
    <child link="link1_base_connector" />
    <axis xyz="0 0 0" />
  </joint>
  <link name="link1_motor_holder">
    <inertial>
      <origin xyz="-5.01820807130571E-14 0.0102439720821413 0.0484515092209075" rpy="0 0 0" />
      <mass value="0.0472357381724757" />
      <inertia ixx="0.000129972797985735" ixy="7.57422861461972E-17" ixz="5.0252648576416E-14" iyy="9.69913160495726E-05" iyz="-4.58591894562E-09" izz="3.3178297068652E-05" />
    </inertial>
    <visual>
      <origin xyz="0 0 0" rpy="0 0 0" />
      <geometry>
        <mesh filename="package://newmanip_description/meshes/link1_motor_holder.STL" />
      </geometry>
      <material name="">
        <color rgba="0.627450980392157 0.627450980392157 0.627450980392157 1" />
      </material>
    </visual>
    <collision>
      <origin xyz="0 0 0" rpy="0 0 0" />
      <geometry>
        <mesh filename="package://newmanip_description/meshes/link1_motor_holder.STL" />
      </geometry>
    </collision>
  </link>
  <joint name="link1_motor_holder_j_link1_base_connector" type="fixed">
    <origin xyz="-0.0475 -0.010235 0.0325" rpy="0 0 0" />
    <parent link="link1_base_connector" />
    <child link="link1_motor_holder" />
    <axis xyz="0 0 0" />
  </joint>
  <link name="link1_holder_plate1">
    <inertial>
      <origin xyz="-7.59478585334872E-05 0.0302376768181887 0.0532016958918762" rpy="0 0 0" />
      <mass value="0.0534173325460069" />
      <inertia ixx="0.000146682680726942" ixy="-1.06020409384096E-11" ixz="1.49286094539467E-07" iyy="0.000109985302453133" iyz="7.03231800187629E-09" izz="3.69574692009433E-05" />
    </inertial>
    <visual>
      <origin xyz="0 0 0" rpy="0 0 0" />
      <geometry>
        <mesh filename="package://newmanip_description/meshes/link1_holder_plate1.STL" />
      </geometry>
      <material name="">
        <color rgba="0.627450980392157 0.627450980392157 0.627450980392157 1" />
      </material>
    </visual>
    <collision>
      <origin xyz="0 0 0" rpy="0 0 0" />
      <geometry>
        <mesh filename="package://newmanip_description/meshes/link1_holder_plate1.STL" />
      </geometry>
    </collision>
  </link>
  <joint name="link1_holder_plate1_j_link1_base_connector" type="fixed">
    <origin xyz="0.0425 -0.030235 0.0325" rpy="0 0 0" />
    <parent link="link1_base_connector" />
    <child link="link1_holder_plate1" />
    <axis xyz="0 0 0" />
  </joint>
  <link name="link1_holder_plate_2">
    <inertial>
      <origin xyz="6.66133814775094E-16 0.0302374993702151 0.057469700426654" rpy="0 0 0" />
      <mass value="0.048340470503894" />
      <inertia ixx="0.000126171826754474" ixy="1.06018937826447E-19" ixz="-1.40627336671772E-18" iyy="9.57171643871991E-05" iyz="6.11742086252551E-09" izz="3.05835702886188E-05" />
    </inertial>
    <visual>
      <origin xyz="0 0 0" rpy="0 0 0" />
      <geometry>
        <mesh filename="package://newmanip_description/meshes/link1_holder_plate_2.STL" />
      </geometry>
      <material name="">
        <color rgba="0.627450980392157 0.627450980392157 0.627450980392157 1" />
      </material>
    </visual>
    <collision>
      <origin xyz="0 0 0" rpy="0 0 0" />
      <geometry>
        <mesh filename="package://newmanip_description/meshes/link1_holder_plate_2.STL" />
      </geometry>
    </collision>
  </link>
  <joint name="link1_holder_plate2_j_plate1" type="fixed">
    <origin xyz="0.047 -0.030235 0.0325" rpy="0 0 0" />
    <parent link="link1_base_connector" />
    <child link="link1_holder_plate_2" />
    <axis xyz="0 0 0" />
  </joint>
  <link name="link1_bottom">
    <inertial>
      <origin xyz="-0.043858301946271 2.53706144981436E-09 0.0175036982186831" rpy="0 0 0" />
      <mass value="0.33776487197569" />
      <inertia ixx="0.00033772543614853" ixy="-3.46909757097291E-12" ixz="5.12404937468018E-06" iyy="0.000417922135939936" iyz="1.10059853231461E-11" izz="0.0003075355761408" />
    </inertial>
    <visual>
      <origin xyz="0 0 0" rpy="0 0 0" />
      <geometry>
        <mesh filename="package://newmanip_description/meshes/link1_bottom.STL" />
      </geometry>
      <material name="">
        <color rgba="0.964705882352941 0.964705882352941 0.952941176470588 1" />
      </material>
    </visual>
    <collision>
      <origin xyz="0 0 0" rpy="0 0 0" />
      <geometry>
        <mesh filename="package://newmanip_description/meshes/link1_bottom.STL" />
      </geometry>
    </collision>
  </link>
  <joint name="lin1_bottom_j_motor_holder_plate2" type="revolute">
    <origin xyz="-0.004775 0.030235 0.09" rpy="0 0 0" />
    <parent link="link1_holder_plate_2" />
    <child link="link1_bottom" />
    <axis xyz="-1 0 0" />
    <limit lower="-1.0" upper="0.0" effort="5" velocity="300" />
  </joint>
  <link name="link1">
    <inertial>
      <origin xyz="-5.39581868075345E-09 -1.69612222045146E-08 0.260067885294572" rpy="0 0 0" />
      <mass value="1.16262072100872" />
      <inertia ixx="0.0294764717399224" ixy="2.64070289134653E-08" ixz="3.02264641415134E-09" iyy="0.0294766138223382" iyz="-6.05581113367684E-09" izz="0.000654113236446206" />
    </inertial>
    <visual>
      <origin xyz="0 0 0" rpy="0 0 0" />
      <geometry>
        <mesh filename="package://newmanip_description/meshes/link1.STL" />
      </geometry>
      <material name="">
        <color rgba="0.0980392156862745 0.0980392156862745 0.0980392156862745 1" />
      </material>
    </visual>
    <collision>
      <origin xyz="0 0 0" rpy="0 0 0" />
      <geometry>
        <mesh filename="package://newmanip_description/meshes/link1.STL" />
      </geometry>
    </collision>
  </link>
  <joint name="link1_j_link1_bottom" type="fixed">
    <origin xyz="-0.044725 0 0.055" rpy="0 0 0" />
    <parent link="link1_bottom" />
    <child link="link1" />
    <axis xyz="0 0 0" />
  </joint>
  <link name="link1_end_part">
    <inertial>
      <origin xyz="3.49700294943744E-07 -5.36573157017273E-08 0.0025745156955117" rpy="0 0 0" />
      <mass value="0.0887935549462749" />
      <inertia ixx="6.05870122823914E-05" ixy="-1.20673426212271E-11" ixz="1.34987864310752E-11" iyy="8.18529027888766E-05" iyz="-3.93645552324886E-13" izz="0.000124952192875935" />
    </inertial>
    <visual>
      <origin xyz="0 0 0" rpy="0 0 0" />
      <geometry>
        <mesh filename="package://newmanip_description/meshes/link1_end_part.STL" />
      </geometry>
      <material name="">
        <color rgba="0.768627450980392 0.207843137254902 0.152941176470588 1" />
      </material>
    </visual>
    <collision>
      <origin xyz="0 0 0" rpy="0 0 0" />
      <geometry>
        <mesh filename="package://newmanip_description/meshes/link1_end_part.STL" />
      </geometry>
    </collision>
  </link>
  <joint name="link1_end_part_j_link1" type="fixed">
    <origin xyz="0 0 0.51997" rpy="0 0 0" />
    <parent link="link1" />
    <child link="link1_end_part" />
    <axis xyz="0 0 0" />
  </joint>
  <link name="link2_holder_plate">
    <inertial>
      <origin xyz="-2.01196429752137E-05 7.42303459810856E-08 0.0581704451095113" rpy="0 0 0" />
      <mass value="0.0587346240548899" />
      <inertia ixx="0.00016111589583289" ixy="1.06567062915207E-12" ixz="3.89385339679009E-08" iyy="0.000126130278788689" iyz="1.31250923946133E-11" izz="3.52646621936093E-05" />
    </inertial>
    <visual>
      <origin xyz="0 0 0" rpy="0 0 0" />
      <geometry>
        <mesh filename="package://newmanip_description/meshes/link2_holder_plate.STL" />
      </geometry>
      <material name="">
        <color rgba="0.627450980392157 0.627450980392157 0.627450980392157 1" />
      </material>
    </visual>
    <collision>
      <origin xyz="0 0 0" rpy="0 0 0" />
      <geometry>
        <mesh filename="package://newmanip_description/meshes/link2_holder_plate.STL" />
      </geometry>
    </collision>
  </link>
  <joint name="link2_holder_plate_j_link1_endpart" type="fixed">
    <origin xyz="0.0425 0 0.0094039" rpy="0 0 0" />
    <parent link="link1_end_part" />
    <child link="link2_holder_plate" />
    <axis xyz="0 0 0" />
  </joint>
  <link name="link2_base_holder">
    <inertial>
      <origin xyz="-0.0396701193420625 -0.0198734327497784 -2.57427568595148E-07" rpy="0 0 0" />
      <mass value="0.334451491213555" />
      <inertia ixx="0.000352606274559091" ixy="-3.68775904581431E-06" ixz="9.85102576858203E-13" iyy="0.000277425037448963" iyz="-1.92982150605619E-11" izz="0.000399176202587073" />
    </inertial>
    <visual>
      <origin xyz="0 0 0" rpy="0 0 0" />
      <geometry>
        <mesh filename="package://newmanip_description/meshes/link2_base_holder.STL" />
      </geometry>
      <material name="">
        <color rgba="0.964705882352941 0.964705882352941 0.952941176470588 1" />
      </material>
    </visual>
    <collision>
      <origin xyz="0 0 0" rpy="0 0 0" />
      <geometry>
        <mesh filename="package://newmanip_description/meshes/link2_base_holder.STL" />
      </geometry>
    </collision>
  </link>
  <joint name="link2_base_holder_j_link2_holder_plate" type="revolute">
    <origin xyz="-0.0022749 0 0.091125" rpy="0 0 0" />
    <parent link="link2_holder_plate" />
    <child link="link2_base_holder" />
    <axis xyz="-1 0 0" />
    <limit lower="-0.85" upper="0.85" effort="5" velocity="300" />
  </joint>
  <link name="link2">
    <inertial>
      <origin xyz="-3.2036842068095E-09 -0.210020758728246 3.06611558364978E-09" rpy="0 0 0" />
      <mass value="0.738793048590477" />
      <inertia ixx="0.0125138808760153" ixy="2.81531282534996E-11" ixz="2.36623911843703E-11" iyy="0.000267941556387362" iyz="4.69560000685452E-11" izz="0.0125149718463103" />
    </inertial>
    <visual>
      <origin xyz="0 0 0" rpy="0 0 0" />
      <geometry>
        <mesh filename="package://newmanip_description/meshes/link2.STL" />
      </geometry>
      <material name="">
        <color rgba="0.0980392156862745 0.0980392156862745 0.0980392156862745 1" />
      </material>
    </visual>
    <collision>
      <origin xyz="0 0 0" rpy="0 0 0" />
      <geometry>
        <mesh filename="package://newmanip_description/meshes/link2.STL" />
      </geometry>
    </collision>
  </link>
  <joint name="link2_j_link2_bottom" type="fixed">
    <origin xyz="-0.040225 -0.055 0" rpy="0 0 0" />
    <parent link="link2_base_holder" />
    <child link="link2" />
    <axis xyz="0 0 0" />
  </joint>
  <link name="link3_holder">
    <inertial>
      <origin xyz="1.04092800823352E-07 -0.0212951513452504 -7.80283795864811E-05" rpy="0 0 0" />
      <mass value="0.188164308449144" />
      <inertia ixx="0.000263210714322179" ixy="1.19504902122293E-09" ixz="4.12755228449986E-11" iyy="0.000217666445518385" iyz="-2.0692789254073E-07" izz="0.000312157989750956" />
    </inertial>
    <visual>
      <origin xyz="0 0 0" rpy="0 0 0" />
      <geometry>
        <mesh filename="package://newmanip_description/meshes/link3_holder.STL" />
      </geometry>
      <material name="">
        <color rgba="0.768627450980392 0.207843137254902 0.152941176470588 1" />
      </material>
    </visual>
    <collision>
      <origin xyz="0 0 0" rpy="0 0 0" />
      <geometry>
        <mesh filename="package://newmanip_description/meshes/link3_holder.STL" />
      </geometry>
    </collision>
  </link>
  <joint name="link3_holder_j_link2" type="fixed">
    <origin xyz="0 -0.41558 0" rpy="0 0 0" />
    <parent link="link2" />
    <child link="link3_holder" />
    <axis xyz="0 0 0" />
  </joint>
  <link name="link3">
    <inertial>
      <origin xyz="-0.0169999999422197 -0.01892736028304 -6.04970303303975E-05" rpy="0 0 0" />
      <mass value="0.186401761983701" />
      <inertia ixx="0.00041649103061218" ixy="3.34702334402905E-13" ixz="-3.13694565292869E-11" iyy="0.000184673919396029" iyz="-1.00161394749398E-06" izz="0.000448406474476473" />
    </inertial>
    <visual>
      <origin xyz="0 0 0" rpy="0 0 0" />
      <geometry>
        <mesh filename="package://newmanip_description/meshes/link3.STL" />
      </geometry>
      <material name="">
        <color rgba="0.627450980392157 0.627450980392157 0.627450980392157 1" />
      </material>
    </visual>
    <collision>
      <origin xyz="0 0 0" rpy="0 0 0" />
      <geometry>
        <mesh filename="package://newmanip_description/meshes/link3.STL" />
      </geometry>
    </collision>
  </link>
  <joint name="link3_j_link3_holder" type="fixed">
    <origin xyz="0.017 -0.065388 0" rpy="0 0 0" />
    <parent link="link3_holder" />
    <child link="link3" />
    <axis xyz="0 0 0" />
  </joint>
  <link name="bevel_2_1">
    <inertial>
      <origin xyz="-0.00198768283371575 4.61148896846453E-11 -6.90960622051762E-11" rpy="0 0 0" />
      <mass value="0.0392764387724245" />
      <inertia ixx="9.38677349018228E-06" ixy="3.28897900019598E-14" ixz="-2.48284275580556E-14" iyy="9.32983228228972E-06" iyz="-4.95150376085659E-16" izz="9.32983227817736E-06" />
    </inertial>
    <visual>
      <origin xyz="0 0 0" rpy="0 0 0" />
      <geometry>
        <mesh filename="package://newmanip_description/meshes/bevel_2_1.STL" />
      </geometry>
      <material name="">
        <color rgba="0.627450980392157 0.627450980392157 0.627450980392157 1" />
      </material>
    </visual>
    <collision>
      <origin xyz="0 0 0" rpy="0 0 0" />
      <geometry>
        <mesh filename="package://newmanip_description/meshes/bevel_2_1.STL" />
      </geometry>
    </collision>
  </link>
  <joint name="bevel_2_1_j_link3" type="revolute">
    <origin xyz="0.024311 -0.064641 -0.00015997" rpy="0 0 0" />
    <parent link="link3" />
    <child link="bevel_2_1" />
    <axis xyz="-1 0 0" />
    <limit lower="-0.2" upper="3.14" effort="5" velocity="300" />
  </joint>
  <link name="link3_coupler">
    <inertial>
      <origin xyz="-5.82388929926125E-05 6.31850608294737E-05 0.00122932281260923" rpy="0 0 0" />
      <mass value="0.0167222714991286" />
      <inertia ixx="2.02973783240983E-06" ixy="1.06542374992194E-10" ixz="5.07256991235962E-10" iyy="3.61055369765391E-06" iyz="-5.45281201822252E-10" izz="3.89529398167193E-06" />
    </inertial>
    <visual>
      <origin xyz="0 0 0" rpy="0 0 0" />
      <geometry>
        <mesh filename="package://newmanip_description/meshes/link3_coupler.STL" />
      </geometry>
      <material name="">
        <color rgba="0.627450980392157 0.627450980392157 0.627450980392157 1" />
      </material>
    </visual>
    <collision>
      <origin xyz="0 0 0" rpy="0 0 0" />
      <geometry>
        <mesh filename="package://newmanip_description/meshes/link3_coupler.STL" />
      </geometry>
    </collision>
  </link>
  <joint name="link3_coupler_j_bevel_2_1" type="fixed">
    <origin xyz="-0.039112 -0.00018086 -0.0017479" rpy="0 0 0" />
    <parent link="bevel_2_1" />
    <child link="link3_coupler" />
    <axis xyz="0 0 -1" />
    <limit lower="0" upper="-3.14" effort="5" velocity="300" />
  </joint>
  <link name="bevel1">
    <inertial>
      <origin xyz="-7.70539188010844E-12 -1.26052945859101E-10 0.00346916742513037" rpy="0 0 0" />
      <mass value="0.0389255764607632" />
      <inertia ixx="7.4012826126844E-06" ixy="1.27861267831252E-15" ixz="8.75309317586799E-15" iyy="7.40128260914493E-06" iyz="8.08425734285388E-14" izz="8.03729543400708E-06" />
    </inertial>
    <visual>
      <origin xyz="0 0 0" rpy="0 0 0" />
      <geometry>
        <mesh filename="package://newmanip_description/meshes/bevel1.STL" />
      </geometry>
      <material name="">
        <color rgba="0.627450980392157 0.627450980392157 0.627450980392157 1" />
      </material>
    </visual>
    <collision>
      <origin xyz="0 0 0" rpy="0 0 0" />
      <geometry>
        <mesh filename="package://newmanip_description/meshes/bevel1.STL" />
      </geometry>
    </collision>
  </link>
  <joint name="bevel1_j_link3_coupler" type="revolute">
    <origin xyz="0 0 -0.037478" rpy="0 0 0" />
    <parent link="link3_coupler" />
    <child link="bevel1" />
    <axis xyz="0 0 -1" />
    <limit lower="0" upper="6.28" effort="5" velocity="300" />
  </joint>
  <link name="gripper">
    <inertial>
      <origin xyz="0.00947390082512833 -3.16404236144763E-10 -0.0326962287167527" rpy="0 0 0" />
      <mass value="0.341464156501707" />
      <inertia ixx="0.000604244616606819" ixy="1.38650343886313E-12" ixz="0.000143274518301015" iyy="0.00239586527325236" iyz="-3.96987708690604E-12" izz="0.00198563943102793" />
    </inertial>
    <visual>
      <origin xyz="0 0 0" rpy="0 0 0" />
      <geometry>
        <mesh filename="package://newmanip_description/meshes/gripper.STL" />
      </geometry>
      <material name="">
        <color rgba="0.964705882352941 0.964705882352941 0.952941176470588 1" />
      </material>
    </visual>
    <collision>
      <origin xyz="0 0 0" rpy="0 0 0" />
      <geometry>
        <mesh filename="package://newmanip_description/meshes/gripper.STL" />
      </geometry>
    </collision>
  </link>
  <joint name="gripper_j_bevel1" type="fixed">
    <origin xyz="0 0 -0.029432" rpy="0 0 0" />
    <parent link="bevel1" />
    <child link="gripper" />
    <axis xyz="0 0 0" />
    <limit lower="0" upper="6.28" effort="5" velocity="300" />
  </joint>
  <link name="ss_rod">
    <inertial>
      <origin xyz="0.1075 7.105427357601E-15 5.88520343569598E-11" rpy="0 0 0" />
      <mass value="0.00282743338823081" />
      <inertia ixx="5.65486677646163E-09" ixy="-4.26106075205144E-20" ixz="-6.52806601260074E-15" iyy="1.1931062039987E-05" iyz="-2.33254048897856E-29" izz="1.1931062039987E-05" />
    </inertial>
    <visual>
      <origin xyz="0 0 0" rpy="0 0 0" />
      <geometry>
        <mesh filename="package://newmanip_description/meshes/ss_rod.STL" />
      </geometry>
      <material name="">
        <color rgba="0.627450980392157 0.627450980392157 0.627450980392157 1" />
      </material>
    </visual>
    <collision>
      <origin xyz="0 0 0" rpy="0 0 0" />
      <geometry>
        <mesh filename="package://newmanip_description/meshes/ss_rod.STL" />
      </geometry>
    </collision>
  </link>
  <joint name="ss_rod_j_gripper" type="fixed">
    <origin xyz="-0.1025 0 -0.041068" rpy="0 0 0" />
    <parent link="gripper" />
    <child link="ss_rod" />
    <axis xyz="0 0 0" />
  </joint>
  <link name="spurgear1">
    <inertial>
      <origin xyz="0.01073269105099 -6.21724893790088E-15 5.86419801607008E-12" rpy="0 0 0" />
      <mass value="0.017095911870029" />
      <inertia ixx="2.6664867878511E-06" ixy="1.85129689989352E-19" ixz="2.79946888523974E-16" iyy="2.15564617596662E-06" iyz="-1.23291483113597E-15" izz="2.15564618008356E-06" />
    </inertial>
    <visual>
      <origin xyz="0 0 0" rpy="0 0 0" />
      <geometry>
        <mesh filename="package://newmanip_description/meshes/spurgear1.STL" />
      </geometry>
      <material name="">
        <color rgba="0.627450980392157 0.627450980392157 0.627450980392157 1" />
      </material>
    </visual>
    <collision>
      <origin xyz="0 0 0" rpy="0 0 0" />
      <geometry>
        <mesh filename="package://newmanip_description/meshes/spurgear1.STL" />
      </geometry>
    </collision>
  </link>
  <joint name="spur_gear1_j_gripper" type="fixed">
    <origin xyz="-0.1277 0 -0.077068" rpy="0 0 0" />
    <parent link="gripper" />
    <child link="spurgear1" />
    <axis xyz="-1 0 0" />
    <limit lower="0" upper="6.28" effort="5" velocity="300" />
  </joint>
  <link name="threded_rod_up">
    <inertial>
      <origin xyz="0 2.22044604925031E-16 2.22044604925031E-16" rpy="0 0 0" />
      <mass value="0.0121489228511336" />
      <inertia ixx="9.39627397423046E-08" ixy="-2.25918058139595E-19" ixz="-3.461185052434E-14" iyy="6.33226212195255E-05" iyz="-1.23669450529155E-28" izz="6.33226212195255E-05" />
    </inertial>
    <visual>
      <origin xyz="0 0 0" rpy="0 0 0" />
      <geometry>
        <mesh filename="package://newmanip_description/meshes/threded_rod_up.STL" />
      </geometry>
      <material name="">
        <color rgba="0.627450980392157 0.627450980392157 0.627450980392157 1" />
      </material>
    </visual>
    <collision>
      <origin xyz="0 0 0" rpy="0 0 0" />
      <geometry>
        <mesh filename="package://newmanip_description/meshes/threded_rod_up.STL" />
      </geometry>
    </collision>
  </link>
  <joint name="threded_jod_j_gripper" type="fixed">
    <origin xyz="0.0175 0 -0.077068" rpy="0 0 0" />
    <parent link="gripper" />
    <child link="threded_rod_up" />
    <axis xyz="-1 0 0" />
    <limit lower="0" upper="0" effort="0" velocity="0" />
  </joint>
  <link name="claw1">
    <inertial>
      <origin xyz="0.00575880746643986 -3.50262773762822E-06 -0.0565127254748121" rpy="0 0 0" />
      <mass value="0.134410672799192" />
      <inertia ixx="0.000371952908783262" ixy="5.5004465774372E-09" ixz="3.30601034472799E-05" iyy="0.000362575120952862" iyz="-2.02998931758679E-09" izz="2.71292076973183E-05" />
    </inertial>
    <visual>
      <origin xyz="0 0 0" rpy="0 0 0" />
      <geometry>
        <mesh filename="package://newmanip_description/meshes/claw1.STL" />
      </geometry>
      <material name="">
        <color rgba="0.964705882352941 0.964705882352941 0.952941176470588 1" />
      </material>
    </visual>
    <collision>
      <origin xyz="0 0 0" rpy="0 0 0" />
      <geometry>
        <mesh filename="package://newmanip_description/meshes/claw1.STL" />
      </geometry>
    </collision>
  </link>
  <joint name="claw1_j_threded_rod_up" type="prismatic">
    <origin xyz="-0.1075 0 0" rpy="0 0 0" />
    <parent link="threded_rod_up" />
    <child link="claw1" />
    <axis xyz="-1 0 0" />
    <limit lower="-0.05" upper="0.05" effort="5" velocity="300" />
    <mimic joint="claw2_j_threded_rod_down" multiplier="-1.0" offset="0.0"/>
  </joint>
  <link name="shaft_coupler">
    <inertial>
      <origin xyz="-3.34353145170496E-09 -2.21470920447331E-06 2.20177151222245E-06" rpy="0 0 0" />
      <mass value="0.00642699869056132" />
      <inertia ixx="2.90757461608025E-07" ixy="1.22521912944497E-13" ixz="9.59361453548064E-14" iyy="6.22257888518885E-07" iyz="-1.54341930965944E-10" izz="6.22256087053553E-07" />
    </inertial>
    <visual>
      <origin xyz="0 0 0" rpy="0 0 0" />
      <geometry>
        <mesh filename="package://newmanip_description/meshes/shaft_coupler.STL" />
      </geometry>
      <material name="">
        <color rgba="0.627450980392157 0.627450980392157 0.627450980392157 1" />
      </material>
    </visual>
    <collision>
      <origin xyz="0 0 0" rpy="0 0 0" />
      <geometry>
        <mesh filename="package://newmanip_description/meshes/shaft_coupler.STL" />
      </geometry>
    </collision>
  </link>
  <joint name="shaft_coupller_j_gripper" type="fixed">
    <origin xyz="0.081 0.00015741 -0.077225" rpy="0 0 0" />
    <parent link="gripper" />
    <child link="shaft_coupler" />
    <axis xyz="0 0 0" />
  </joint>
  <link name="motor">
    <inertial>
      <origin xyz="0.0211379514351595 6.88338275267597E-15 1.29814665295047E-05" rpy="0 0 0" />
      <mass value="0.0558864492200027" />
      <inertia ixx="5.79372255972707E-06" ixy="-1.11395473946062E-19" ixz="-2.38707164672831E-08" iyy="3.78491735617808E-05" iyz="1.20433601788769E-21" izz="3.78610357361111E-05" />
    </inertial>
    <visual>
      <origin xyz="0 0 0" rpy="0 0 0" />
      <geometry>
        <mesh filename="package://newmanip_description/meshes/motor.STL" />
      </geometry>
      <material name="">
        <color rgba="0.627450980392157 0.627450980392157 0.627450980392157 1" />
      </material>
    </visual>
    <collision>
      <origin xyz="0 0 0" rpy="0 0 0" />
      <geometry>
        <mesh filename="package://newmanip_description/meshes/motor.STL" />
      </geometry>
    </collision>
  </link>
  <joint name="motor_j_gripper" type="fixed">
    <origin xyz="0.1225 0 -0.077068" rpy="0 0 0" />
    <parent link="gripper" />
    <child link="motor" />
    <axis xyz="0 0 0" />
  </joint>
  <link name="spur_gear2">
    <inertial>
      <origin xyz="0.0107326910509882 -2.88657986402541E-15 5.86020121318143E-12" rpy="0 0 0" />
      <mass value="0.0170959118700088" />
      <inertia ixx="2.6664867878468E-06" ixy="8.3549543536952E-20" ixz="2.80075169711451E-16" iyy="2.15564617575233E-06" iyz="-7.75564904852259E-16" izz="2.15564618029305E-06" />
    </inertial>
    <visual>
      <origin xyz="0 0 0" rpy="0 0 0" />
      <geometry>
        <mesh filename="package://newmanip_description/meshes/spur_gear2.STL" />
      </geometry>
      <material name="">
        <color rgba="0.627450980392157 0.627450980392157 0.627450980392157 1" />
      </material>
    </visual>
    <collision>
      <origin xyz="0 0 0" rpy="0 0 0" />
      <geometry>
        <mesh filename="package://newmanip_description/meshes/spur_gear2.STL" />
      </geometry>
    </collision>
  </link>
  <joint name="spur_gear2_j_gripper" type="fixed">
    <origin xyz="-0.1277 0 -0.11487" rpy="0 0 0" />
    <parent link="gripper" />
    <child link="spur_gear2" />
    <axis xyz="-1 0 0" />
    <limit lower="0" upper="6.28" effort="5" velocity="300" />
  </joint>
  <link name="threded_rod_down">
    <inertial>
      <origin xyz="4.44089209850063E-16 0 -4.44089209850063E-16" rpy="0 0 0" />
      <mass value="0.0121489228511336" />
      <inertia ixx="9.39627397423046E-08" ixy="-2.25918058139595E-19" ixz="-3.461185052434E-14" iyy="6.33226212195255E-05" iyz="-1.23669450529155E-28" izz="6.33226212195255E-05" />
    </inertial>
    <visual>
      <origin xyz="0 0 0" rpy="0 0 0" />
      <geometry>
        <mesh filename="package://newmanip_description/meshes/threded_rod_down.STL" />
      </geometry>
      <material name="">
        <color rgba="0.627450980392157 0.627450980392157 0.627450980392157 1" />
      </material>
    </visual>
    <collision>
      <origin xyz="0 0 0" rpy="0 0 0" />
      <geometry>
        <mesh filename="package://newmanip_description/meshes/threded_rod_down.STL" />
      </geometry>
    </collision>
  </link>
  <joint name="threded_rod_down_j_gripper" type="fixed">
    <origin xyz="0.0175 0 -0.11487" rpy="0 0 0" />
    <parent link="gripper" />
    <child link="threded_rod_down" />
    <axis xyz="-1 0 0" />
    <limit lower="0" upper="0" effort="0" velocity="0" />
  </joint>
  <link name="claw2">
    <inertial>
      <origin xyz="-0.00575880742509649 3.50262773896048E-06 -0.0190127254811181" rpy="0 0 0" />
      <mass value="0.134410672799188" />
      <inertia ixx="0.000371952908855641" ixy="5.50044657641857E-09" ixz="-3.30601030697604E-05" iyy="0.000362575120952851" iyz="2.02998932900778E-09" izz="2.71292076249286E-05" />
    </inertial>
    <visual>
      <origin xyz="0 0 0" rpy="0 0 0" />
      <geometry>
        <mesh filename="package://newmanip_description/meshes/claw2.STL" />
      </geometry>
      <material name="">
        <color rgba="0.964705882352941 0.964705882352941 0.952941176470588 1" />
      </material>
    </visual>
    <collision>
      <origin xyz="0 0 0" rpy="0 0 0" />
      <geometry>
        <mesh filename="package://newmanip_description/meshes/claw2.STL" />
      </geometry>
    </collision>
  </link>
  <joint name="claw2_j_threded_rod_down" type="prismatic">
    <origin xyz="0.041 0 0.000299" rpy="0 0 0" />
    <parent link="threded_rod_down" />
    <child link="claw2" />
    <axis xyz="-1 0 0" />
    <limit lower="0" upper="0.04" effort="5" velocity="0.03" />
  </joint>
  <link name="bevel_2_2">
    <inertial>
      <origin xyz="0.00198768283371975 8.5286000484075E-11 8.57451887270599E-11" rpy="0 0 0" />
      <mass value="0.0392764387724469" />
      <inertia ixx="9.38677349018948E-06" ixy="-5.1670018267452E-14" ixz="-4.17556208174296E-14" iyy="9.32983228157335E-06" iyz="-1.61680580364253E-15" izz="9.3298322789013E-06" />
    </inertial>
    <visual>
      <origin xyz="0 0 0" rpy="0 0 0" />
      <geometry>
        <mesh filename="package://newmanip_description/meshes/bevel_2_2.STL" />
      </geometry>
      <material name="">
        <color rgba="0.627450980392157 0.627450980392157 0.627450980392157 1" />
      </material>
    </visual>
    <collision>
      <origin xyz="0 0 0" rpy="0 0 0" />
      <geometry>
        <mesh filename="package://newmanip_description/meshes/bevel_2_2.STL" />
      </geometry>
    </collision>
  </link>
  <joint name="bevel_2_2_j_link3" type="revolute">
    <origin xyz="-0.058311 -0.064641 -0.00015997" rpy="0 0 0" />
    <parent link="link3" />
    <child link="bevel_2_2" />
    <axis xyz="-1 0 0" />
    <limit lower="-0.2" upper="3.14" effort="5" velocity="300" />
    <mimic joint="bevel_2_1_j_link3" multiplier="1.0" offset="0.0" />
  </joint>
  <link name="link2_motor_holder">
    <inertial>
      <origin xyz="-2.56259458097929E-11 8.04152539002345E-08 0.046877021806319" rpy="0 0 0" />
      <mass value="0.043743804004434" />
      <inertia ixx="0.00012449983939246" ixy="3.41065754728543E-18" ixz="5.29237705775377E-14" iyy="9.68442144708896E-05" iyz="-2.03364458424434E-11" izz="2.78378906768312E-05" />
    </inertial>
    <visual>
      <origin xyz="0 0 0" rpy="0 0 0" />
      <geometry>
        <mesh filename="package://newmanip_description/meshes/link2_motor_holder.STL" />
      </geometry>
      <material name="">
        <color rgba="0.627450980392157 0.627450980392157 0.627450980392157 1" />
      </material>
    </visual>
    <collision>
      <origin xyz="0 0 0" rpy="0 0 0" />
      <geometry>
        <mesh filename="package://newmanip_description/meshes/link2_motor_holder.STL" />
      </geometry>
    </collision>
  </link>
  <joint name="link2_motor_holder_j_link1_endpart" type="fixed">
    <origin xyz="-0.0425 0 0.0094039" rpy="0 0 0" />
    <parent link="link1_end_part" />
    <child link="link2_motor_holder" />
    <axis xyz="0 0 0" />
  </joint>
</robot>
